<?xml version="1.0" encoding="UTF-8"?>
<testng-results ignored="0" total="9" passed="1" failed="8" skipped="0">
  <reporter-output>
  </reporter-output>
  <suite started-at="2023-11-20T11:48:40 IST" name="Default suite" finished-at="2023-11-20T11:52:01 IST" duration-ms="200505">
    <groups>
      <group name="Signup">
        <method signature="Done_SignUpModuleNegativeScenarios_StgTest.whileSignIntoApplicationExistingEmailGivenErrorTest()[pri:1, instance:S2_Negative_Scenarious_for_SignupLoginSchemesDepositAmountSprint_1_Stg.Done_SignUpModuleNegativeScenarios_StgTest@689604d9]" name="whileSignIntoApplicationExistingEmailGivenErrorTest" class="S2_Negative_Scenarious_for_SignupLoginSchemesDepositAmountSprint_1_Stg.Done_SignUpModuleNegativeScenarios_StgTest"/>
        <method signature="Done_SignUpModuleNegativeScenarios_StgTest.whileSignIntoApplicationExistingPhoneNumberGivenErrorTest()[pri:2, instance:S2_Negative_Scenarious_for_SignupLoginSchemesDepositAmountSprint_1_Stg.Done_SignUpModuleNegativeScenarios_StgTest@689604d9]" name="whileSignIntoApplicationExistingPhoneNumberGivenErrorTest" class="S2_Negative_Scenarious_for_SignupLoginSchemesDepositAmountSprint_1_Stg.Done_SignUpModuleNegativeScenarios_StgTest"/>
        <method signature="Done_SignUpModuleNegativeScenarios_StgTest.whileSignIntoApplicationPhoneNumberNotGivenErrorTest()[pri:3, instance:S2_Negative_Scenarious_for_SignupLoginSchemesDepositAmountSprint_1_Stg.Done_SignUpModuleNegativeScenarios_StgTest@689604d9]" name="whileSignIntoApplicationPhoneNumberNotGivenErrorTest" class="S2_Negative_Scenarious_for_SignupLoginSchemesDepositAmountSprint_1_Stg.Done_SignUpModuleNegativeScenarios_StgTest"/>
        <method signature="Done_SignUpModuleNegativeScenarios_StgTest.whileSignIntoApplicationGivenWrongReferralCodeErrorTest()[pri:4, instance:S2_Negative_Scenarious_for_SignupLoginSchemesDepositAmountSprint_1_Stg.Done_SignUpModuleNegativeScenarios_StgTest@689604d9]" name="whileSignIntoApplicationGivenWrongReferralCodeErrorTest" class="S2_Negative_Scenarious_for_SignupLoginSchemesDepositAmountSprint_1_Stg.Done_SignUpModuleNegativeScenarios_StgTest"/>
        <method signature="Done_SignUpModuleNegativeScenarios_StgTest.whileSignIntoApplicationGivenRightReferralCodePassedTest()[pri:5, instance:S2_Negative_Scenarious_for_SignupLoginSchemesDepositAmountSprint_1_Stg.Done_SignUpModuleNegativeScenarios_StgTest@689604d9]" name="whileSignIntoApplicationGivenRightReferralCodePassedTest" class="S2_Negative_Scenarious_for_SignupLoginSchemesDepositAmountSprint_1_Stg.Done_SignUpModuleNegativeScenarios_StgTest"/>
        <method signature="Done_SignUpModuleNegativeScenarios_StgTest.whileSignIntoApplicationSkipNameErrorTest()[pri:6, instance:S2_Negative_Scenarious_for_SignupLoginSchemesDepositAmountSprint_1_Stg.Done_SignUpModuleNegativeScenarios_StgTest@689604d9]" name="whileSignIntoApplicationSkipNameErrorTest" class="S2_Negative_Scenarious_for_SignupLoginSchemesDepositAmountSprint_1_Stg.Done_SignUpModuleNegativeScenarios_StgTest"/>
        <method signature="Done_SignUpModuleNegativeScenarios_StgTest.whileSignIntoApplicationSkipHeardAboutUsDropDwnValueErrorTest()[pri:7, instance:S2_Negative_Scenarious_for_SignupLoginSchemesDepositAmountSprint_1_Stg.Done_SignUpModuleNegativeScenarios_StgTest@689604d9]" name="whileSignIntoApplicationSkipHeardAboutUsDropDwnValueErrorTest" class="S2_Negative_Scenarious_for_SignupLoginSchemesDepositAmountSprint_1_Stg.Done_SignUpModuleNegativeScenarios_StgTest"/>
        <method signature="Done_SignUpModuleNegativeScenarios_StgTest.whileSignIntoApplicationEnterMoreThan10NumbersInMobileNumTextFieldErrorTest()[pri:8, instance:S2_Negative_Scenarious_for_SignupLoginSchemesDepositAmountSprint_1_Stg.Done_SignUpModuleNegativeScenarios_StgTest@689604d9]" name="whileSignIntoApplicationEnterMoreThan10NumbersInMobileNumTextFieldErrorTest" class="S2_Negative_Scenarious_for_SignupLoginSchemesDepositAmountSprint_1_Stg.Done_SignUpModuleNegativeScenarios_StgTest"/>
        <method signature="Done_SignUpModuleNegativeScenarios_StgTest.whileSignIntoApplicationGivenInvalidEmailErrorTest()[pri:9, instance:S2_Negative_Scenarious_for_SignupLoginSchemesDepositAmountSprint_1_Stg.Done_SignUpModuleNegativeScenarios_StgTest@689604d9]" name="whileSignIntoApplicationGivenInvalidEmailErrorTest" class="S2_Negative_Scenarious_for_SignupLoginSchemesDepositAmountSprint_1_Stg.Done_SignUpModuleNegativeScenarios_StgTest"/>
      </group> <!-- Signup -->
    </groups>
    <test started-at="2023-11-20T11:48:40 IST" name="Default test" finished-at="2023-11-20T11:52:01 IST" duration-ms="200505">
      <class name="S2_Negative_Scenarious_for_SignupLoginSchemesDepositAmountSprint_1_Stg.Done_SignUpModuleNegativeScenarios_StgTest">
        <test-method signature="whileSignIntoApplicationExistingEmailGivenErrorTest()[pri:1, instance:S2_Negative_Scenarious_for_SignupLoginSchemesDepositAmountSprint_1_Stg.Done_SignUpModuleNegativeScenarios_StgTest@689604d9]" started-at="2023-11-20T11:48:40 IST" name="whileSignIntoApplicationExistingEmailGivenErrorTest" finished-at="2023-11-20T11:49:13 IST" duration-ms="32687" status="FAIL">
          <exception class="java.lang.AssertionError">
            <message>
              <![CDATA[null]]>
            </message>
            <full-stacktrace>
              <![CDATA[java.lang.AssertionError: null
at org.testng.Assert.fail(Assert.java:110)
at org.testng.Assert.fail(Assert.java:115)
at S2_Negative_Scenarious_for_SignupLoginSchemesDepositAmountSprint_1_Stg.Done_SignUpModuleNegativeScenarios_StgTest.whileSignIntoApplicationExistingEmailGivenErrorTest(Done_SignUpModuleNegativeScenarios_StgTest.java:260)
at java.base/jdk.internal.reflect.DirectMethodHandleAccessor.invoke(DirectMethodHandleAccessor.java:104)
at java.base/java.lang.reflect.Method.invoke(Method.java:577)
at org.testng.internal.invokers.MethodInvocationHelper.invokeMethod(MethodInvocationHelper.java:139)
at org.testng.internal.invokers.TestInvoker.invokeMethod(TestInvoker.java:677)
at org.testng.internal.invokers.TestInvoker.invokeTestMethod(TestInvoker.java:221)
at org.testng.internal.invokers.MethodRunner.runInSequence(MethodRunner.java:50)
at org.testng.internal.invokers.TestInvoker$MethodInvocationAgent.invoke(TestInvoker.java:962)
at org.testng.internal.invokers.TestInvoker.invokeTestMethods(TestInvoker.java:194)
at org.testng.internal.invokers.TestMethodWorker.invokeTestMethods(TestMethodWorker.java:148)
at org.testng.internal.invokers.TestMethodWorker.run(TestMethodWorker.java:128)
at java.base/java.util.ArrayList.forEach(ArrayList.java:1511)
at org.testng.TestRunner.privateRun(TestRunner.java:806)
at org.testng.TestRunner.run(TestRunner.java:601)
at org.testng.SuiteRunner.runTest(SuiteRunner.java:433)
at org.testng.SuiteRunner.runSequentially(SuiteRunner.java:427)
at org.testng.SuiteRunner.privateRun(SuiteRunner.java:387)
at org.testng.SuiteRunner.run(SuiteRunner.java:330)
at org.testng.SuiteRunnerWorker.runSuite(SuiteRunnerWorker.java:52)
at org.testng.SuiteRunnerWorker.run(SuiteRunnerWorker.java:95)
at org.testng.TestNG.runSuitesSequentially(TestNG.java:1256)
at org.testng.TestNG.runSuitesLocally(TestNG.java:1176)
at org.testng.TestNG.runSuites(TestNG.java:1099)
at org.testng.TestNG.run(TestNG.java:1067)
at org.testng.remote.AbstractRemoteTestNG.run(AbstractRemoteTestNG.java:115)
at org.testng.remote.RemoteTestNG.initAndRun(RemoteTestNG.java:251)
at org.testng.remote.RemoteTestNG.main(RemoteTestNG.java:77)
]]>
            </full-stacktrace>
          </exception> <!-- java.lang.AssertionError -->
          <reporter-output>
          </reporter-output>
        </test-method> <!-- whileSignIntoApplicationExistingEmailGivenErrorTest -->
        <test-method signature="whileSignIntoApplicationExistingPhoneNumberGivenErrorTest()[pri:2, instance:S2_Negative_Scenarious_for_SignupLoginSchemesDepositAmountSprint_1_Stg.Done_SignUpModuleNegativeScenarios_StgTest@689604d9]" started-at="2023-11-20T11:49:13 IST" name="whileSignIntoApplicationExistingPhoneNumberGivenErrorTest" finished-at="2023-11-20T11:49:44 IST" duration-ms="31170" status="FAIL">
          <exception class="java.lang.AssertionError">
            <message>
              <![CDATA[null]]>
            </message>
            <full-stacktrace>
              <![CDATA[java.lang.AssertionError: null
at org.testng.Assert.fail(Assert.java:110)
at org.testng.Assert.fail(Assert.java:115)
at S2_Negative_Scenarious_for_SignupLoginSchemesDepositAmountSprint_1_Stg.Done_SignUpModuleNegativeScenarios_StgTest.whileSignIntoApplicationExistingPhoneNumberGivenErrorTest(Done_SignUpModuleNegativeScenarios_StgTest.java:355)
at java.base/jdk.internal.reflect.DirectMethodHandleAccessor.invoke(DirectMethodHandleAccessor.java:104)
at java.base/java.lang.reflect.Method.invoke(Method.java:577)
at org.testng.internal.invokers.MethodInvocationHelper.invokeMethod(MethodInvocationHelper.java:139)
at org.testng.internal.invokers.TestInvoker.invokeMethod(TestInvoker.java:677)
at org.testng.internal.invokers.TestInvoker.invokeTestMethod(TestInvoker.java:221)
at org.testng.internal.invokers.MethodRunner.runInSequence(MethodRunner.java:50)
at org.testng.internal.invokers.TestInvoker$MethodInvocationAgent.invoke(TestInvoker.java:962)
at org.testng.internal.invokers.TestInvoker.invokeTestMethods(TestInvoker.java:194)
at org.testng.internal.invokers.TestMethodWorker.invokeTestMethods(TestMethodWorker.java:148)
at org.testng.internal.invokers.TestMethodWorker.run(TestMethodWorker.java:128)
at java.base/java.util.ArrayList.forEach(ArrayList.java:1511)
at org.testng.TestRunner.privateRun(TestRunner.java:806)
at org.testng.TestRunner.run(TestRunner.java:601)
at org.testng.SuiteRunner.runTest(SuiteRunner.java:433)
at org.testng.SuiteRunner.runSequentially(SuiteRunner.java:427)
at org.testng.SuiteRunner.privateRun(SuiteRunner.java:387)
at org.testng.SuiteRunner.run(SuiteRunner.java:330)
at org.testng.SuiteRunnerWorker.runSuite(SuiteRunnerWorker.java:52)
at org.testng.SuiteRunnerWorker.run(SuiteRunnerWorker.java:95)
at org.testng.TestNG.runSuitesSequentially(TestNG.java:1256)
at org.testng.TestNG.runSuitesLocally(TestNG.java:1176)
at org.testng.TestNG.runSuites(TestNG.java:1099)
at org.testng.TestNG.run(TestNG.java:1067)
at org.testng.remote.AbstractRemoteTestNG.run(AbstractRemoteTestNG.java:115)
at org.testng.remote.RemoteTestNG.initAndRun(RemoteTestNG.java:251)
at org.testng.remote.RemoteTestNG.main(RemoteTestNG.java:77)
]]>
            </full-stacktrace>
          </exception> <!-- java.lang.AssertionError -->
          <reporter-output>
          </reporter-output>
        </test-method> <!-- whileSignIntoApplicationExistingPhoneNumberGivenErrorTest -->
        <test-method signature="whileSignIntoApplicationPhoneNumberNotGivenErrorTest()[pri:3, instance:S2_Negative_Scenarious_for_SignupLoginSchemesDepositAmountSprint_1_Stg.Done_SignUpModuleNegativeScenarios_StgTest@689604d9]" started-at="2023-11-20T11:49:44 IST" name="whileSignIntoApplicationPhoneNumberNotGivenErrorTest" finished-at="2023-11-20T11:50:02 IST" duration-ms="17993" status="FAIL">
          <exception class="java.lang.AssertionError">
            <message>
              <![CDATA[null]]>
            </message>
            <full-stacktrace>
              <![CDATA[java.lang.AssertionError: null
at org.testng.Assert.fail(Assert.java:110)
at org.testng.Assert.fail(Assert.java:115)
at S2_Negative_Scenarious_for_SignupLoginSchemesDepositAmountSprint_1_Stg.Done_SignUpModuleNegativeScenarios_StgTest.whileSignIntoApplicationPhoneNumberNotGivenErrorTest(Done_SignUpModuleNegativeScenarios_StgTest.java:430)
at java.base/jdk.internal.reflect.DirectMethodHandleAccessor.invoke(DirectMethodHandleAccessor.java:104)
at java.base/java.lang.reflect.Method.invoke(Method.java:577)
at org.testng.internal.invokers.MethodInvocationHelper.invokeMethod(MethodInvocationHelper.java:139)
at org.testng.internal.invokers.TestInvoker.invokeMethod(TestInvoker.java:677)
at org.testng.internal.invokers.TestInvoker.invokeTestMethod(TestInvoker.java:221)
at org.testng.internal.invokers.MethodRunner.runInSequence(MethodRunner.java:50)
at org.testng.internal.invokers.TestInvoker$MethodInvocationAgent.invoke(TestInvoker.java:962)
at org.testng.internal.invokers.TestInvoker.invokeTestMethods(TestInvoker.java:194)
at org.testng.internal.invokers.TestMethodWorker.invokeTestMethods(TestMethodWorker.java:148)
at org.testng.internal.invokers.TestMethodWorker.run(TestMethodWorker.java:128)
at java.base/java.util.ArrayList.forEach(ArrayList.java:1511)
at org.testng.TestRunner.privateRun(TestRunner.java:806)
at org.testng.TestRunner.run(TestRunner.java:601)
at org.testng.SuiteRunner.runTest(SuiteRunner.java:433)
at org.testng.SuiteRunner.runSequentially(SuiteRunner.java:427)
at org.testng.SuiteRunner.privateRun(SuiteRunner.java:387)
at org.testng.SuiteRunner.run(SuiteRunner.java:330)
at org.testng.SuiteRunnerWorker.runSuite(SuiteRunnerWorker.java:52)
at org.testng.SuiteRunnerWorker.run(SuiteRunnerWorker.java:95)
at org.testng.TestNG.runSuitesSequentially(TestNG.java:1256)
at org.testng.TestNG.runSuitesLocally(TestNG.java:1176)
at org.testng.TestNG.runSuites(TestNG.java:1099)
at org.testng.TestNG.run(TestNG.java:1067)
at org.testng.remote.AbstractRemoteTestNG.run(AbstractRemoteTestNG.java:115)
at org.testng.remote.RemoteTestNG.initAndRun(RemoteTestNG.java:251)
at org.testng.remote.RemoteTestNG.main(RemoteTestNG.java:77)
]]>
            </full-stacktrace>
          </exception> <!-- java.lang.AssertionError -->
          <reporter-output>
          </reporter-output>
        </test-method> <!-- whileSignIntoApplicationPhoneNumberNotGivenErrorTest -->
        <test-method signature="whileSignIntoApplicationGivenWrongReferralCodeErrorTest()[pri:4, instance:S2_Negative_Scenarious_for_SignupLoginSchemesDepositAmountSprint_1_Stg.Done_SignUpModuleNegativeScenarios_StgTest@689604d9]" started-at="2023-11-20T11:50:02 IST" name="whileSignIntoApplicationGivenWrongReferralCodeErrorTest" finished-at="2023-11-20T11:50:20 IST" duration-ms="18188" status="FAIL">
          <exception class="java.lang.AssertionError">
            <message>
              <![CDATA[null]]>
            </message>
            <full-stacktrace>
              <![CDATA[java.lang.AssertionError: null
at org.testng.Assert.fail(Assert.java:110)
at org.testng.Assert.fail(Assert.java:115)
at S2_Negative_Scenarious_for_SignupLoginSchemesDepositAmountSprint_1_Stg.Done_SignUpModuleNegativeScenarios_StgTest.whileSignIntoApplicationGivenWrongReferralCodeErrorTest(Done_SignUpModuleNegativeScenarios_StgTest.java:520)
at java.base/jdk.internal.reflect.DirectMethodHandleAccessor.invoke(DirectMethodHandleAccessor.java:104)
at java.base/java.lang.reflect.Method.invoke(Method.java:577)
at org.testng.internal.invokers.MethodInvocationHelper.invokeMethod(MethodInvocationHelper.java:139)
at org.testng.internal.invokers.TestInvoker.invokeMethod(TestInvoker.java:677)
at org.testng.internal.invokers.TestInvoker.invokeTestMethod(TestInvoker.java:221)
at org.testng.internal.invokers.MethodRunner.runInSequence(MethodRunner.java:50)
at org.testng.internal.invokers.TestInvoker$MethodInvocationAgent.invoke(TestInvoker.java:962)
at org.testng.internal.invokers.TestInvoker.invokeTestMethods(TestInvoker.java:194)
at org.testng.internal.invokers.TestMethodWorker.invokeTestMethods(TestMethodWorker.java:148)
at org.testng.internal.invokers.TestMethodWorker.run(TestMethodWorker.java:128)
at java.base/java.util.ArrayList.forEach(ArrayList.java:1511)
at org.testng.TestRunner.privateRun(TestRunner.java:806)
at org.testng.TestRunner.run(TestRunner.java:601)
at org.testng.SuiteRunner.runTest(SuiteRunner.java:433)
at org.testng.SuiteRunner.runSequentially(SuiteRunner.java:427)
at org.testng.SuiteRunner.privateRun(SuiteRunner.java:387)
at org.testng.SuiteRunner.run(SuiteRunner.java:330)
at org.testng.SuiteRunnerWorker.runSuite(SuiteRunnerWorker.java:52)
at org.testng.SuiteRunnerWorker.run(SuiteRunnerWorker.java:95)
at org.testng.TestNG.runSuitesSequentially(TestNG.java:1256)
at org.testng.TestNG.runSuitesLocally(TestNG.java:1176)
at org.testng.TestNG.runSuites(TestNG.java:1099)
at org.testng.TestNG.run(TestNG.java:1067)
at org.testng.remote.AbstractRemoteTestNG.run(AbstractRemoteTestNG.java:115)
at org.testng.remote.RemoteTestNG.initAndRun(RemoteTestNG.java:251)
at org.testng.remote.RemoteTestNG.main(RemoteTestNG.java:77)
]]>
            </full-stacktrace>
          </exception> <!-- java.lang.AssertionError -->
          <reporter-output>
          </reporter-output>
        </test-method> <!-- whileSignIntoApplicationGivenWrongReferralCodeErrorTest -->
        <test-method signature="whileSignIntoApplicationGivenRightReferralCodePassedTest()[pri:5, instance:S2_Negative_Scenarious_for_SignupLoginSchemesDepositAmountSprint_1_Stg.Done_SignUpModuleNegativeScenarios_StgTest@689604d9]" started-at="2023-11-20T11:50:20 IST" name="whileSignIntoApplicationGivenRightReferralCodePassedTest" finished-at="2023-11-20T11:50:39 IST" duration-ms="18207" status="FAIL">
          <exception class="java.lang.AssertionError">
            <message>
              <![CDATA[null]]>
            </message>
            <full-stacktrace>
              <![CDATA[java.lang.AssertionError: null
at org.testng.Assert.fail(Assert.java:110)
at org.testng.Assert.fail(Assert.java:115)
at S2_Negative_Scenarious_for_SignupLoginSchemesDepositAmountSprint_1_Stg.Done_SignUpModuleNegativeScenarios_StgTest.whileSignIntoApplicationGivenRightReferralCodePassedTest(Done_SignUpModuleNegativeScenarios_StgTest.java:591)
at java.base/jdk.internal.reflect.DirectMethodHandleAccessor.invoke(DirectMethodHandleAccessor.java:104)
at java.base/java.lang.reflect.Method.invoke(Method.java:577)
at org.testng.internal.invokers.MethodInvocationHelper.invokeMethod(MethodInvocationHelper.java:139)
at org.testng.internal.invokers.TestInvoker.invokeMethod(TestInvoker.java:677)
at org.testng.internal.invokers.TestInvoker.invokeTestMethod(TestInvoker.java:221)
at org.testng.internal.invokers.MethodRunner.runInSequence(MethodRunner.java:50)
at org.testng.internal.invokers.TestInvoker$MethodInvocationAgent.invoke(TestInvoker.java:962)
at org.testng.internal.invokers.TestInvoker.invokeTestMethods(TestInvoker.java:194)
at org.testng.internal.invokers.TestMethodWorker.invokeTestMethods(TestMethodWorker.java:148)
at org.testng.internal.invokers.TestMethodWorker.run(TestMethodWorker.java:128)
at java.base/java.util.ArrayList.forEach(ArrayList.java:1511)
at org.testng.TestRunner.privateRun(TestRunner.java:806)
at org.testng.TestRunner.run(TestRunner.java:601)
at org.testng.SuiteRunner.runTest(SuiteRunner.java:433)
at org.testng.SuiteRunner.runSequentially(SuiteRunner.java:427)
at org.testng.SuiteRunner.privateRun(SuiteRunner.java:387)
at org.testng.SuiteRunner.run(SuiteRunner.java:330)
at org.testng.SuiteRunnerWorker.runSuite(SuiteRunnerWorker.java:52)
at org.testng.SuiteRunnerWorker.run(SuiteRunnerWorker.java:95)
at org.testng.TestNG.runSuitesSequentially(TestNG.java:1256)
at org.testng.TestNG.runSuitesLocally(TestNG.java:1176)
at org.testng.TestNG.runSuites(TestNG.java:1099)
at org.testng.TestNG.run(TestNG.java:1067)
at org.testng.remote.AbstractRemoteTestNG.run(AbstractRemoteTestNG.java:115)
at org.testng.remote.RemoteTestNG.initAndRun(RemoteTestNG.java:251)
at org.testng.remote.RemoteTestNG.main(RemoteTestNG.java:77)
]]>
            </full-stacktrace>
          </exception> <!-- java.lang.AssertionError -->
          <reporter-output>
          </reporter-output>
        </test-method> <!-- whileSignIntoApplicationGivenRightReferralCodePassedTest -->
        <test-method signature="whileSignIntoApplicationSkipNameErrorTest()[pri:6, instance:S2_Negative_Scenarious_for_SignupLoginSchemesDepositAmountSprint_1_Stg.Done_SignUpModuleNegativeScenarios_StgTest@689604d9]" started-at="2023-11-20T11:50:39 IST" name="whileSignIntoApplicationSkipNameErrorTest" finished-at="2023-11-20T11:50:59 IST" duration-ms="20484" status="FAIL">
          <exception class="java.lang.AssertionError">
            <message>
              <![CDATA[null]]>
            </message>
            <full-stacktrace>
              <![CDATA[java.lang.AssertionError: null
at org.testng.Assert.fail(Assert.java:110)
at org.testng.Assert.fail(Assert.java:115)
at S2_Negative_Scenarious_for_SignupLoginSchemesDepositAmountSprint_1_Stg.Done_SignUpModuleNegativeScenarios_StgTest.whileSignIntoApplicationSkipNameErrorTest(Done_SignUpModuleNegativeScenarios_StgTest.java:667)
at java.base/jdk.internal.reflect.DirectMethodHandleAccessor.invoke(DirectMethodHandleAccessor.java:104)
at java.base/java.lang.reflect.Method.invoke(Method.java:577)
at org.testng.internal.invokers.MethodInvocationHelper.invokeMethod(MethodInvocationHelper.java:139)
at org.testng.internal.invokers.TestInvoker.invokeMethod(TestInvoker.java:677)
at org.testng.internal.invokers.TestInvoker.invokeTestMethod(TestInvoker.java:221)
at org.testng.internal.invokers.MethodRunner.runInSequence(MethodRunner.java:50)
at org.testng.internal.invokers.TestInvoker$MethodInvocationAgent.invoke(TestInvoker.java:962)
at org.testng.internal.invokers.TestInvoker.invokeTestMethods(TestInvoker.java:194)
at org.testng.internal.invokers.TestMethodWorker.invokeTestMethods(TestMethodWorker.java:148)
at org.testng.internal.invokers.TestMethodWorker.run(TestMethodWorker.java:128)
at java.base/java.util.ArrayList.forEach(ArrayList.java:1511)
at org.testng.TestRunner.privateRun(TestRunner.java:806)
at org.testng.TestRunner.run(TestRunner.java:601)
at org.testng.SuiteRunner.runTest(SuiteRunner.java:433)
at org.testng.SuiteRunner.runSequentially(SuiteRunner.java:427)
at org.testng.SuiteRunner.privateRun(SuiteRunner.java:387)
at org.testng.SuiteRunner.run(SuiteRunner.java:330)
at org.testng.SuiteRunnerWorker.runSuite(SuiteRunnerWorker.java:52)
at org.testng.SuiteRunnerWorker.run(SuiteRunnerWorker.java:95)
at org.testng.TestNG.runSuitesSequentially(TestNG.java:1256)
at org.testng.TestNG.runSuitesLocally(TestNG.java:1176)
at org.testng.TestNG.runSuites(TestNG.java:1099)
at org.testng.TestNG.run(TestNG.java:1067)
at org.testng.remote.AbstractRemoteTestNG.run(AbstractRemoteTestNG.java:115)
at org.testng.remote.RemoteTestNG.initAndRun(RemoteTestNG.java:251)
at org.testng.remote.RemoteTestNG.main(RemoteTestNG.java:77)
]]>
            </full-stacktrace>
          </exception> <!-- java.lang.AssertionError -->
          <reporter-output>
          </reporter-output>
        </test-method> <!-- whileSignIntoApplicationSkipNameErrorTest -->
        <test-method signature="whileSignIntoApplicationSkipHeardAboutUsDropDwnValueErrorTest()[pri:7, instance:S2_Negative_Scenarious_for_SignupLoginSchemesDepositAmountSprint_1_Stg.Done_SignUpModuleNegativeScenarios_StgTest@689604d9]" started-at="2023-11-20T11:50:59 IST" name="whileSignIntoApplicationSkipHeardAboutUsDropDwnValueErrorTest" finished-at="2023-11-20T11:51:15 IST" duration-ms="16092" status="FAIL">
          <exception class="java.lang.AssertionError">
            <message>
              <![CDATA[null]]>
            </message>
            <full-stacktrace>
              <![CDATA[java.lang.AssertionError: null
at org.testng.Assert.fail(Assert.java:110)
at org.testng.Assert.fail(Assert.java:115)
at S2_Negative_Scenarious_for_SignupLoginSchemesDepositAmountSprint_1_Stg.Done_SignUpModuleNegativeScenarios_StgTest.whileSignIntoApplicationSkipHeardAboutUsDropDwnValueErrorTest(Done_SignUpModuleNegativeScenarios_StgTest.java:737)
at java.base/jdk.internal.reflect.DirectMethodHandleAccessor.invoke(DirectMethodHandleAccessor.java:104)
at java.base/java.lang.reflect.Method.invoke(Method.java:577)
at org.testng.internal.invokers.MethodInvocationHelper.invokeMethod(MethodInvocationHelper.java:139)
at org.testng.internal.invokers.TestInvoker.invokeMethod(TestInvoker.java:677)
at org.testng.internal.invokers.TestInvoker.invokeTestMethod(TestInvoker.java:221)
at org.testng.internal.invokers.MethodRunner.runInSequence(MethodRunner.java:50)
at org.testng.internal.invokers.TestInvoker$MethodInvocationAgent.invoke(TestInvoker.java:962)
at org.testng.internal.invokers.TestInvoker.invokeTestMethods(TestInvoker.java:194)
at org.testng.internal.invokers.TestMethodWorker.invokeTestMethods(TestMethodWorker.java:148)
at org.testng.internal.invokers.TestMethodWorker.run(TestMethodWorker.java:128)
at java.base/java.util.ArrayList.forEach(ArrayList.java:1511)
at org.testng.TestRunner.privateRun(TestRunner.java:806)
at org.testng.TestRunner.run(TestRunner.java:601)
at org.testng.SuiteRunner.runTest(SuiteRunner.java:433)
at org.testng.SuiteRunner.runSequentially(SuiteRunner.java:427)
at org.testng.SuiteRunner.privateRun(SuiteRunner.java:387)
at org.testng.SuiteRunner.run(SuiteRunner.java:330)
at org.testng.SuiteRunnerWorker.runSuite(SuiteRunnerWorker.java:52)
at org.testng.SuiteRunnerWorker.run(SuiteRunnerWorker.java:95)
at org.testng.TestNG.runSuitesSequentially(TestNG.java:1256)
at org.testng.TestNG.runSuitesLocally(TestNG.java:1176)
at org.testng.TestNG.runSuites(TestNG.java:1099)
at org.testng.TestNG.run(TestNG.java:1067)
at org.testng.remote.AbstractRemoteTestNG.run(AbstractRemoteTestNG.java:115)
at org.testng.remote.RemoteTestNG.initAndRun(RemoteTestNG.java:251)
at org.testng.remote.RemoteTestNG.main(RemoteTestNG.java:77)
]]>
            </full-stacktrace>
          </exception> <!-- java.lang.AssertionError -->
          <reporter-output>
          </reporter-output>
        </test-method> <!-- whileSignIntoApplicationSkipHeardAboutUsDropDwnValueErrorTest -->
        <test-method signature="whileSignIntoApplicationEnterMoreThan10NumbersInMobileNumTextFieldErrorTest()[pri:8, instance:S2_Negative_Scenarious_for_SignupLoginSchemesDepositAmountSprint_1_Stg.Done_SignUpModuleNegativeScenarios_StgTest@689604d9]" started-at="2023-11-20T11:51:15 IST" name="whileSignIntoApplicationEnterMoreThan10NumbersInMobileNumTextFieldErrorTest" finished-at="2023-11-20T11:51:34 IST" duration-ms="18397" status="FAIL">
          <exception class="java.lang.AssertionError">
            <message>
              <![CDATA[null]]>
            </message>
            <full-stacktrace>
              <![CDATA[java.lang.AssertionError: null
at org.testng.Assert.fail(Assert.java:110)
at org.testng.Assert.fail(Assert.java:115)
at S2_Negative_Scenarious_for_SignupLoginSchemesDepositAmountSprint_1_Stg.Done_SignUpModuleNegativeScenarios_StgTest.whileSignIntoApplicationEnterMoreThan10NumbersInMobileNumTextFieldErrorTest(Done_SignUpModuleNegativeScenarios_StgTest.java:807)
at java.base/jdk.internal.reflect.DirectMethodHandleAccessor.invoke(DirectMethodHandleAccessor.java:104)
at java.base/java.lang.reflect.Method.invoke(Method.java:577)
at org.testng.internal.invokers.MethodInvocationHelper.invokeMethod(MethodInvocationHelper.java:139)
at org.testng.internal.invokers.TestInvoker.invokeMethod(TestInvoker.java:677)
at org.testng.internal.invokers.TestInvoker.invokeTestMethod(TestInvoker.java:221)
at org.testng.internal.invokers.MethodRunner.runInSequence(MethodRunner.java:50)
at org.testng.internal.invokers.TestInvoker$MethodInvocationAgent.invoke(TestInvoker.java:962)
at org.testng.internal.invokers.TestInvoker.invokeTestMethods(TestInvoker.java:194)
at org.testng.internal.invokers.TestMethodWorker.invokeTestMethods(TestMethodWorker.java:148)
at org.testng.internal.invokers.TestMethodWorker.run(TestMethodWorker.java:128)
at java.base/java.util.ArrayList.forEach(ArrayList.java:1511)
at org.testng.TestRunner.privateRun(TestRunner.java:806)
at org.testng.TestRunner.run(TestRunner.java:601)
at org.testng.SuiteRunner.runTest(SuiteRunner.java:433)
at org.testng.SuiteRunner.runSequentially(SuiteRunner.java:427)
at org.testng.SuiteRunner.privateRun(SuiteRunner.java:387)
at org.testng.SuiteRunner.run(SuiteRunner.java:330)
at org.testng.SuiteRunnerWorker.runSuite(SuiteRunnerWorker.java:52)
at org.testng.SuiteRunnerWorker.run(SuiteRunnerWorker.java:95)
at org.testng.TestNG.runSuitesSequentially(TestNG.java:1256)
at org.testng.TestNG.runSuitesLocally(TestNG.java:1176)
at org.testng.TestNG.runSuites(TestNG.java:1099)
at org.testng.TestNG.run(TestNG.java:1067)
at org.testng.remote.AbstractRemoteTestNG.run(AbstractRemoteTestNG.java:115)
at org.testng.remote.RemoteTestNG.initAndRun(RemoteTestNG.java:251)
at org.testng.remote.RemoteTestNG.main(RemoteTestNG.java:77)
]]>
            </full-stacktrace>
          </exception> <!-- java.lang.AssertionError -->
          <reporter-output>
          </reporter-output>
        </test-method> <!-- whileSignIntoApplicationEnterMoreThan10NumbersInMobileNumTextFieldErrorTest -->
        <test-method signature="whileSignIntoApplicationGivenInvalidEmailErrorTest()[pri:9, instance:S2_Negative_Scenarious_for_SignupLoginSchemesDepositAmountSprint_1_Stg.Done_SignUpModuleNegativeScenarios_StgTest@689604d9]" started-at="2023-11-20T11:51:34 IST" name="whileSignIntoApplicationGivenInvalidEmailErrorTest" finished-at="2023-11-20T11:52:01 IST" duration-ms="27241" status="PASS">
          <reporter-output>
          </reporter-output>
        </test-method> <!-- whileSignIntoApplicationGivenInvalidEmailErrorTest -->
      </class> <!-- S2_Negative_Scenarious_for_SignupLoginSchemesDepositAmountSprint_1_Stg.Done_SignUpModuleNegativeScenarios_StgTest -->
    </test> <!-- Default test -->
  </suite> <!-- Default suite -->
</testng-results>
