<?xml version="1.0" encoding="UTF-8"?>
<!-- Generated by org.testng.reporters.JUnitReportReporter -->
<testsuite hostname="Vicky" failures="11" tests="11" name="S2_Negative_Scenarious_for_SignupLoginSchemesDepositAmountSprint_1_Stg.Done_LoginErrors_StgTest" time="111.344" errors="0" timestamp="2023-11-20T15:07:25 IST" skipped="0">
  <testcase classname="S2_Negative_Scenarious_for_SignupLoginSchemesDepositAmountSprint_1_Stg.Done_LoginErrors_StgTest" name="loginByGivingAlreadyRegisteredMobileNumberOTPTest" time="10.727">
    <failure message="null" type="java.lang.AssertionError">
      <![CDATA[java.lang.AssertionError: null
at org.testng.Assert.fail(Assert.java:110)
at org.testng.Assert.fail(Assert.java:115)
at S2_Negative_Scenarious_for_SignupLoginSchemesDepositAmountSprint_1_Stg.Done_LoginErrors_StgTest.loginByGivingAlreadyRegisteredMobileNumberOTPTest(Done_LoginErrors_StgTest.java:86)
at java.base/jdk.internal.reflect.DirectMethodHandleAccessor.invoke(DirectMethodHandleAccessor.java:104)
at java.base/java.lang.reflect.Method.invoke(Method.java:577)
at org.testng.internal.invokers.MethodInvocationHelper.invokeMethod(MethodInvocationHelper.java:139)
at org.testng.internal.invokers.TestInvoker.invokeMethod(TestInvoker.java:677)
at org.testng.internal.invokers.TestInvoker.invokeTestMethod(TestInvoker.java:221)
at org.testng.internal.invokers.MethodRunner.runInSequence(MethodRunner.java:50)
at org.testng.internal.invokers.TestInvoker$MethodInvocationAgent.invoke(TestInvoker.java:962)
at org.testng.internal.invokers.TestInvoker.invokeTestMethods(TestInvoker.java:194)
at org.testng.internal.invokers.TestMethodWorker.invokeTestMethods(TestMethodWorker.java:148)
at org.testng.internal.invokers.TestMethodWorker.run(TestMethodWorker.java:128)
at java.base/java.util.ArrayList.forEach(ArrayList.java:1511)
at org.testng.TestRunner.privateRun(TestRunner.java:806)
at org.testng.TestRunner.run(TestRunner.java:601)
at org.testng.SuiteRunner.runTest(SuiteRunner.java:433)
at org.testng.SuiteRunner$SuiteWorker.run(SuiteRunner.java:471)
at org.testng.internal.thread.ThreadUtil.lambda$execute$0(ThreadUtil.java:58)
at java.base/java.util.concurrent.FutureTask.run(FutureTask.java:264)
at java.base/java.util.concurrent.ThreadPoolExecutor.runWorker(ThreadPoolExecutor.java:1136)
at java.base/java.util.concurrent.ThreadPoolExecutor$Worker.run(ThreadPoolExecutor.java:635)
at java.base/java.lang.Thread.run(Thread.java:833)
]]>
    </failure>
  </testcase> <!-- loginByGivingAlreadyRegisteredMobileNumberOTPTest -->
  <system-out/>
  <testcase classname="S2_Negative_Scenarious_for_SignupLoginSchemesDepositAmountSprint_1_Stg.Done_LoginErrors_StgTest" name="loginByGivingNotRegisteredMobileNumberErrorTest" time="9.851">
    <failure message="null" type="java.lang.AssertionError">
      <![CDATA[java.lang.AssertionError: null
at org.testng.Assert.fail(Assert.java:110)
at org.testng.Assert.fail(Assert.java:115)
at S2_Negative_Scenarious_for_SignupLoginSchemesDepositAmountSprint_1_Stg.Done_LoginErrors_StgTest.loginByGivingNotRegisteredMobileNumberErrorTest(Done_LoginErrors_StgTest.java:159)
at java.base/jdk.internal.reflect.DirectMethodHandleAccessor.invoke(DirectMethodHandleAccessor.java:104)
at java.base/java.lang.reflect.Method.invoke(Method.java:577)
at org.testng.internal.invokers.MethodInvocationHelper.invokeMethod(MethodInvocationHelper.java:139)
at org.testng.internal.invokers.TestInvoker.invokeMethod(TestInvoker.java:677)
at org.testng.internal.invokers.TestInvoker.invokeTestMethod(TestInvoker.java:221)
at org.testng.internal.invokers.MethodRunner.runInSequence(MethodRunner.java:50)
at org.testng.internal.invokers.TestInvoker$MethodInvocationAgent.invoke(TestInvoker.java:962)
at org.testng.internal.invokers.TestInvoker.invokeTestMethods(TestInvoker.java:194)
at org.testng.internal.invokers.TestMethodWorker.invokeTestMethods(TestMethodWorker.java:148)
at org.testng.internal.invokers.TestMethodWorker.run(TestMethodWorker.java:128)
at java.base/java.util.ArrayList.forEach(ArrayList.java:1511)
at org.testng.TestRunner.privateRun(TestRunner.java:806)
at org.testng.TestRunner.run(TestRunner.java:601)
at org.testng.SuiteRunner.runTest(SuiteRunner.java:433)
at org.testng.SuiteRunner$SuiteWorker.run(SuiteRunner.java:471)
at org.testng.internal.thread.ThreadUtil.lambda$execute$0(ThreadUtil.java:58)
at java.base/java.util.concurrent.FutureTask.run(FutureTask.java:264)
at java.base/java.util.concurrent.ThreadPoolExecutor.runWorker(ThreadPoolExecutor.java:1136)
at java.base/java.util.concurrent.ThreadPoolExecutor$Worker.run(ThreadPoolExecutor.java:635)
at java.base/java.lang.Thread.run(Thread.java:833)
]]>
    </failure>
  </testcase> <!-- loginByGivingNotRegisteredMobileNumberErrorTest -->
  <system-out/>
  <testcase classname="S2_Negative_Scenarious_for_SignupLoginSchemesDepositAmountSprint_1_Stg.Done_LoginErrors_StgTest" name="loginByGiving1NumberAsMobileNumberErrorTest" time="9.905">
    <failure message="null" type="java.lang.AssertionError">
      <![CDATA[java.lang.AssertionError: null
at org.testng.Assert.fail(Assert.java:110)
at org.testng.Assert.fail(Assert.java:115)
at S2_Negative_Scenarious_for_SignupLoginSchemesDepositAmountSprint_1_Stg.Done_LoginErrors_StgTest.loginByGiving1NumberAsMobileNumberErrorTest(Done_LoginErrors_StgTest.java:234)
at java.base/jdk.internal.reflect.DirectMethodHandleAccessor.invoke(DirectMethodHandleAccessor.java:104)
at java.base/java.lang.reflect.Method.invoke(Method.java:577)
at org.testng.internal.invokers.MethodInvocationHelper.invokeMethod(MethodInvocationHelper.java:139)
at org.testng.internal.invokers.TestInvoker.invokeMethod(TestInvoker.java:677)
at org.testng.internal.invokers.TestInvoker.invokeTestMethod(TestInvoker.java:221)
at org.testng.internal.invokers.MethodRunner.runInSequence(MethodRunner.java:50)
at org.testng.internal.invokers.TestInvoker$MethodInvocationAgent.invoke(TestInvoker.java:962)
at org.testng.internal.invokers.TestInvoker.invokeTestMethods(TestInvoker.java:194)
at org.testng.internal.invokers.TestMethodWorker.invokeTestMethods(TestMethodWorker.java:148)
at org.testng.internal.invokers.TestMethodWorker.run(TestMethodWorker.java:128)
at java.base/java.util.ArrayList.forEach(ArrayList.java:1511)
at org.testng.TestRunner.privateRun(TestRunner.java:806)
at org.testng.TestRunner.run(TestRunner.java:601)
at org.testng.SuiteRunner.runTest(SuiteRunner.java:433)
at org.testng.SuiteRunner$SuiteWorker.run(SuiteRunner.java:471)
at org.testng.internal.thread.ThreadUtil.lambda$execute$0(ThreadUtil.java:58)
at java.base/java.util.concurrent.FutureTask.run(FutureTask.java:264)
at java.base/java.util.concurrent.ThreadPoolExecutor.runWorker(ThreadPoolExecutor.java:1136)
at java.base/java.util.concurrent.ThreadPoolExecutor$Worker.run(ThreadPoolExecutor.java:635)
at java.base/java.lang.Thread.run(Thread.java:833)
]]>
    </failure>
  </testcase> <!-- loginByGiving1NumberAsMobileNumberErrorTest -->
  <system-out/>
  <testcase classname="S2_Negative_Scenarious_for_SignupLoginSchemesDepositAmountSprint_1_Stg.Done_LoginErrors_StgTest" name="loginByGiving3NumbersAsMobileNumberErrorTest" time="9.661">
    <failure message="null" type="java.lang.AssertionError">
      <![CDATA[java.lang.AssertionError: null
at org.testng.Assert.fail(Assert.java:110)
at org.testng.Assert.fail(Assert.java:115)
at S2_Negative_Scenarious_for_SignupLoginSchemesDepositAmountSprint_1_Stg.Done_LoginErrors_StgTest.loginByGiving3NumbersAsMobileNumberErrorTest(Done_LoginErrors_StgTest.java:308)
at java.base/jdk.internal.reflect.DirectMethodHandleAccessor.invoke(DirectMethodHandleAccessor.java:104)
at java.base/java.lang.reflect.Method.invoke(Method.java:577)
at org.testng.internal.invokers.MethodInvocationHelper.invokeMethod(MethodInvocationHelper.java:139)
at org.testng.internal.invokers.TestInvoker.invokeMethod(TestInvoker.java:677)
at org.testng.internal.invokers.TestInvoker.invokeTestMethod(TestInvoker.java:221)
at org.testng.internal.invokers.MethodRunner.runInSequence(MethodRunner.java:50)
at org.testng.internal.invokers.TestInvoker$MethodInvocationAgent.invoke(TestInvoker.java:962)
at org.testng.internal.invokers.TestInvoker.invokeTestMethods(TestInvoker.java:194)
at org.testng.internal.invokers.TestMethodWorker.invokeTestMethods(TestMethodWorker.java:148)
at org.testng.internal.invokers.TestMethodWorker.run(TestMethodWorker.java:128)
at java.base/java.util.ArrayList.forEach(ArrayList.java:1511)
at org.testng.TestRunner.privateRun(TestRunner.java:806)
at org.testng.TestRunner.run(TestRunner.java:601)
at org.testng.SuiteRunner.runTest(SuiteRunner.java:433)
at org.testng.SuiteRunner$SuiteWorker.run(SuiteRunner.java:471)
at org.testng.internal.thread.ThreadUtil.lambda$execute$0(ThreadUtil.java:58)
at java.base/java.util.concurrent.FutureTask.run(FutureTask.java:264)
at java.base/java.util.concurrent.ThreadPoolExecutor.runWorker(ThreadPoolExecutor.java:1136)
at java.base/java.util.concurrent.ThreadPoolExecutor$Worker.run(ThreadPoolExecutor.java:635)
at java.base/java.lang.Thread.run(Thread.java:833)
]]>
    </failure>
  </testcase> <!-- loginByGiving3NumbersAsMobileNumberErrorTest -->
  <system-out/>
  <testcase classname="S2_Negative_Scenarious_for_SignupLoginSchemesDepositAmountSprint_1_Stg.Done_LoginErrors_StgTest" name="loginByGivingMoreThan12NumbersAsMobileNumberErrorTest" time="9.728">
    <failure message="null" type="java.lang.AssertionError">
      <![CDATA[java.lang.AssertionError: null
at org.testng.Assert.fail(Assert.java:110)
at org.testng.Assert.fail(Assert.java:115)
at S2_Negative_Scenarious_for_SignupLoginSchemesDepositAmountSprint_1_Stg.Done_LoginErrors_StgTest.loginByGivingMoreThan12NumbersAsMobileNumberErrorTest(Done_LoginErrors_StgTest.java:382)
at java.base/jdk.internal.reflect.DirectMethodHandleAccessor.invoke(DirectMethodHandleAccessor.java:104)
at java.base/java.lang.reflect.Method.invoke(Method.java:577)
at org.testng.internal.invokers.MethodInvocationHelper.invokeMethod(MethodInvocationHelper.java:139)
at org.testng.internal.invokers.TestInvoker.invokeMethod(TestInvoker.java:677)
at org.testng.internal.invokers.TestInvoker.invokeTestMethod(TestInvoker.java:221)
at org.testng.internal.invokers.MethodRunner.runInSequence(MethodRunner.java:50)
at org.testng.internal.invokers.TestInvoker$MethodInvocationAgent.invoke(TestInvoker.java:962)
at org.testng.internal.invokers.TestInvoker.invokeTestMethods(TestInvoker.java:194)
at org.testng.internal.invokers.TestMethodWorker.invokeTestMethods(TestMethodWorker.java:148)
at org.testng.internal.invokers.TestMethodWorker.run(TestMethodWorker.java:128)
at java.base/java.util.ArrayList.forEach(ArrayList.java:1511)
at org.testng.TestRunner.privateRun(TestRunner.java:806)
at org.testng.TestRunner.run(TestRunner.java:601)
at org.testng.SuiteRunner.runTest(SuiteRunner.java:433)
at org.testng.SuiteRunner$SuiteWorker.run(SuiteRunner.java:471)
at org.testng.internal.thread.ThreadUtil.lambda$execute$0(ThreadUtil.java:58)
at java.base/java.util.concurrent.FutureTask.run(FutureTask.java:264)
at java.base/java.util.concurrent.ThreadPoolExecutor.runWorker(ThreadPoolExecutor.java:1136)
at java.base/java.util.concurrent.ThreadPoolExecutor$Worker.run(ThreadPoolExecutor.java:635)
at java.base/java.lang.Thread.run(Thread.java:833)
]]>
    </failure>
  </testcase> <!-- loginByGivingMoreThan12NumbersAsMobileNumberErrorTest -->
  <system-out/>
  <testcase classname="S2_Negative_Scenarious_for_SignupLoginSchemesDepositAmountSprint_1_Stg.Done_LoginErrors_StgTest" name="loginByGivingMoreThan14NumbersAsMobileNumberErrorTest" time="9.514">
    <failure message="null" type="java.lang.AssertionError">
      <![CDATA[java.lang.AssertionError: null
at org.testng.Assert.fail(Assert.java:110)
at org.testng.Assert.fail(Assert.java:115)
at S2_Negative_Scenarious_for_SignupLoginSchemesDepositAmountSprint_1_Stg.Done_LoginErrors_StgTest.loginByGivingMoreThan14NumbersAsMobileNumberErrorTest(Done_LoginErrors_StgTest.java:457)
at java.base/jdk.internal.reflect.DirectMethodHandleAccessor.invoke(DirectMethodHandleAccessor.java:104)
at java.base/java.lang.reflect.Method.invoke(Method.java:577)
at org.testng.internal.invokers.MethodInvocationHelper.invokeMethod(MethodInvocationHelper.java:139)
at org.testng.internal.invokers.TestInvoker.invokeMethod(TestInvoker.java:677)
at org.testng.internal.invokers.TestInvoker.invokeTestMethod(TestInvoker.java:221)
at org.testng.internal.invokers.MethodRunner.runInSequence(MethodRunner.java:50)
at org.testng.internal.invokers.TestInvoker$MethodInvocationAgent.invoke(TestInvoker.java:962)
at org.testng.internal.invokers.TestInvoker.invokeTestMethods(TestInvoker.java:194)
at org.testng.internal.invokers.TestMethodWorker.invokeTestMethods(TestMethodWorker.java:148)
at org.testng.internal.invokers.TestMethodWorker.run(TestMethodWorker.java:128)
at java.base/java.util.ArrayList.forEach(ArrayList.java:1511)
at org.testng.TestRunner.privateRun(TestRunner.java:806)
at org.testng.TestRunner.run(TestRunner.java:601)
at org.testng.SuiteRunner.runTest(SuiteRunner.java:433)
at org.testng.SuiteRunner$SuiteWorker.run(SuiteRunner.java:471)
at org.testng.internal.thread.ThreadUtil.lambda$execute$0(ThreadUtil.java:58)
at java.base/java.util.concurrent.FutureTask.run(FutureTask.java:264)
at java.base/java.util.concurrent.ThreadPoolExecutor.runWorker(ThreadPoolExecutor.java:1136)
at java.base/java.util.concurrent.ThreadPoolExecutor$Worker.run(ThreadPoolExecutor.java:635)
at java.base/java.lang.Thread.run(Thread.java:833)
]]>
    </failure>
  </testcase> <!-- loginByGivingMoreThan14NumbersAsMobileNumberErrorTest -->
  <system-out/>
  <testcase classname="S2_Negative_Scenarious_for_SignupLoginSchemesDepositAmountSprint_1_Stg.Done_LoginErrors_StgTest" name="loginByGivingSpecialCharsAsMobileNumberErrorTest" time="9.820">
    <failure message="null" type="java.lang.AssertionError">
      <![CDATA[java.lang.AssertionError: null
at org.testng.Assert.fail(Assert.java:110)
at org.testng.Assert.fail(Assert.java:115)
at S2_Negative_Scenarious_for_SignupLoginSchemesDepositAmountSprint_1_Stg.Done_LoginErrors_StgTest.loginByGivingSpecialCharsAsMobileNumberErrorTest(Done_LoginErrors_StgTest.java:532)
at java.base/jdk.internal.reflect.DirectMethodHandleAccessor.invoke(DirectMethodHandleAccessor.java:104)
at java.base/java.lang.reflect.Method.invoke(Method.java:577)
at org.testng.internal.invokers.MethodInvocationHelper.invokeMethod(MethodInvocationHelper.java:139)
at org.testng.internal.invokers.TestInvoker.invokeMethod(TestInvoker.java:677)
at org.testng.internal.invokers.TestInvoker.invokeTestMethod(TestInvoker.java:221)
at org.testng.internal.invokers.MethodRunner.runInSequence(MethodRunner.java:50)
at org.testng.internal.invokers.TestInvoker$MethodInvocationAgent.invoke(TestInvoker.java:962)
at org.testng.internal.invokers.TestInvoker.invokeTestMethods(TestInvoker.java:194)
at org.testng.internal.invokers.TestMethodWorker.invokeTestMethods(TestMethodWorker.java:148)
at org.testng.internal.invokers.TestMethodWorker.run(TestMethodWorker.java:128)
at java.base/java.util.ArrayList.forEach(ArrayList.java:1511)
at org.testng.TestRunner.privateRun(TestRunner.java:806)
at org.testng.TestRunner.run(TestRunner.java:601)
at org.testng.SuiteRunner.runTest(SuiteRunner.java:433)
at org.testng.SuiteRunner$SuiteWorker.run(SuiteRunner.java:471)
at org.testng.internal.thread.ThreadUtil.lambda$execute$0(ThreadUtil.java:58)
at java.base/java.util.concurrent.FutureTask.run(FutureTask.java:264)
at java.base/java.util.concurrent.ThreadPoolExecutor.runWorker(ThreadPoolExecutor.java:1136)
at java.base/java.util.concurrent.ThreadPoolExecutor$Worker.run(ThreadPoolExecutor.java:635)
at java.base/java.lang.Thread.run(Thread.java:833)
]]>
    </failure>
  </testcase> <!-- loginByGivingSpecialCharsAsMobileNumberErrorTest -->
  <system-out/>
  <testcase classname="S2_Negative_Scenarious_for_SignupLoginSchemesDepositAmountSprint_1_Stg.Done_LoginErrors_StgTest" name="loginByClickingOnLoginWithGoogleErrorTest" time="11.829">
    <failure message="null" type="java.lang.AssertionError">
      <![CDATA[java.lang.AssertionError: null
at org.testng.Assert.fail(Assert.java:110)
at org.testng.Assert.fail(Assert.java:115)
at S2_Negative_Scenarious_for_SignupLoginSchemesDepositAmountSprint_1_Stg.Done_LoginErrors_StgTest.loginByClickingOnLoginWithGoogleErrorTest(Done_LoginErrors_StgTest.java:685)
at java.base/jdk.internal.reflect.DirectMethodHandleAccessor.invoke(DirectMethodHandleAccessor.java:104)
at java.base/java.lang.reflect.Method.invoke(Method.java:577)
at org.testng.internal.invokers.MethodInvocationHelper.invokeMethod(MethodInvocationHelper.java:139)
at org.testng.internal.invokers.TestInvoker.invokeMethod(TestInvoker.java:677)
at org.testng.internal.invokers.TestInvoker.invokeTestMethod(TestInvoker.java:221)
at org.testng.internal.invokers.MethodRunner.runInSequence(MethodRunner.java:50)
at org.testng.internal.invokers.TestInvoker$MethodInvocationAgent.invoke(TestInvoker.java:962)
at org.testng.internal.invokers.TestInvoker.invokeTestMethods(TestInvoker.java:194)
at org.testng.internal.invokers.TestMethodWorker.invokeTestMethods(TestMethodWorker.java:148)
at org.testng.internal.invokers.TestMethodWorker.run(TestMethodWorker.java:128)
at java.base/java.util.ArrayList.forEach(ArrayList.java:1511)
at org.testng.TestRunner.privateRun(TestRunner.java:806)
at org.testng.TestRunner.run(TestRunner.java:601)
at org.testng.SuiteRunner.runTest(SuiteRunner.java:433)
at org.testng.SuiteRunner$SuiteWorker.run(SuiteRunner.java:471)
at org.testng.internal.thread.ThreadUtil.lambda$execute$0(ThreadUtil.java:58)
at java.base/java.util.concurrent.FutureTask.run(FutureTask.java:264)
at java.base/java.util.concurrent.ThreadPoolExecutor.runWorker(ThreadPoolExecutor.java:1136)
at java.base/java.util.concurrent.ThreadPoolExecutor$Worker.run(ThreadPoolExecutor.java:635)
at java.base/java.lang.Thread.run(Thread.java:833)
]]>
    </failure>
  </testcase> <!-- loginByClickingOnLoginWithGoogleErrorTest -->
  <system-out/>
  <testcase classname="S2_Negative_Scenarious_for_SignupLoginSchemesDepositAmountSprint_1_Stg.Done_LoginErrors_StgTest" name="loginByGivingRegisteredMobileNumberPassTest" time="10.313">
    <failure message="null" type="java.lang.AssertionError">
      <![CDATA[java.lang.AssertionError: null
at org.testng.Assert.fail(Assert.java:110)
at org.testng.Assert.fail(Assert.java:115)
at S2_Negative_Scenarious_for_SignupLoginSchemesDepositAmountSprint_1_Stg.Done_LoginErrors_StgTest.loginByGivingRegisteredMobileNumberPassTest(Done_LoginErrors_StgTest.java:756)
at java.base/jdk.internal.reflect.DirectMethodHandleAccessor.invoke(DirectMethodHandleAccessor.java:104)
at java.base/java.lang.reflect.Method.invoke(Method.java:577)
at org.testng.internal.invokers.MethodInvocationHelper.invokeMethod(MethodInvocationHelper.java:139)
at org.testng.internal.invokers.TestInvoker.invokeMethod(TestInvoker.java:677)
at org.testng.internal.invokers.TestInvoker.invokeTestMethod(TestInvoker.java:221)
at org.testng.internal.invokers.MethodRunner.runInSequence(MethodRunner.java:50)
at org.testng.internal.invokers.TestInvoker$MethodInvocationAgent.invoke(TestInvoker.java:962)
at org.testng.internal.invokers.TestInvoker.invokeTestMethods(TestInvoker.java:194)
at org.testng.internal.invokers.TestMethodWorker.invokeTestMethods(TestMethodWorker.java:148)
at org.testng.internal.invokers.TestMethodWorker.run(TestMethodWorker.java:128)
at java.base/java.util.ArrayList.forEach(ArrayList.java:1511)
at org.testng.TestRunner.privateRun(TestRunner.java:806)
at org.testng.TestRunner.run(TestRunner.java:601)
at org.testng.SuiteRunner.runTest(SuiteRunner.java:433)
at org.testng.SuiteRunner$SuiteWorker.run(SuiteRunner.java:471)
at org.testng.internal.thread.ThreadUtil.lambda$execute$0(ThreadUtil.java:58)
at java.base/java.util.concurrent.FutureTask.run(FutureTask.java:264)
at java.base/java.util.concurrent.ThreadPoolExecutor.runWorker(ThreadPoolExecutor.java:1136)
at java.base/java.util.concurrent.ThreadPoolExecutor$Worker.run(ThreadPoolExecutor.java:635)
at java.base/java.lang.Thread.run(Thread.java:833)
]]>
    </failure>
  </testcase> <!-- loginByGivingRegisteredMobileNumberPassTest -->
  <system-out/>
  <testcase classname="S2_Negative_Scenarious_for_SignupLoginSchemesDepositAmountSprint_1_Stg.Done_LoginErrors_StgTest" name="loginByGiving10NumbersAs0MobileNumberErrorTest" time="9.853">
    <failure message="null" type="java.lang.AssertionError">
      <![CDATA[java.lang.AssertionError: null
at org.testng.Assert.fail(Assert.java:110)
at org.testng.Assert.fail(Assert.java:115)
at S2_Negative_Scenarious_for_SignupLoginSchemesDepositAmountSprint_1_Stg.Done_LoginErrors_StgTest.loginByGiving10NumbersAs0MobileNumberErrorTest(Done_LoginErrors_StgTest.java:825)
at java.base/jdk.internal.reflect.DirectMethodHandleAccessor.invoke(DirectMethodHandleAccessor.java:104)
at java.base/java.lang.reflect.Method.invoke(Method.java:577)
at org.testng.internal.invokers.MethodInvocationHelper.invokeMethod(MethodInvocationHelper.java:139)
at org.testng.internal.invokers.TestInvoker.invokeMethod(TestInvoker.java:677)
at org.testng.internal.invokers.TestInvoker.invokeTestMethod(TestInvoker.java:221)
at org.testng.internal.invokers.MethodRunner.runInSequence(MethodRunner.java:50)
at org.testng.internal.invokers.TestInvoker$MethodInvocationAgent.invoke(TestInvoker.java:962)
at org.testng.internal.invokers.TestInvoker.invokeTestMethods(TestInvoker.java:194)
at org.testng.internal.invokers.TestMethodWorker.invokeTestMethods(TestMethodWorker.java:148)
at org.testng.internal.invokers.TestMethodWorker.run(TestMethodWorker.java:128)
at java.base/java.util.ArrayList.forEach(ArrayList.java:1511)
at org.testng.TestRunner.privateRun(TestRunner.java:806)
at org.testng.TestRunner.run(TestRunner.java:601)
at org.testng.SuiteRunner.runTest(SuiteRunner.java:433)
at org.testng.SuiteRunner$SuiteWorker.run(SuiteRunner.java:471)
at org.testng.internal.thread.ThreadUtil.lambda$execute$0(ThreadUtil.java:58)
at java.base/java.util.concurrent.FutureTask.run(FutureTask.java:264)
at java.base/java.util.concurrent.ThreadPoolExecutor.runWorker(ThreadPoolExecutor.java:1136)
at java.base/java.util.concurrent.ThreadPoolExecutor$Worker.run(ThreadPoolExecutor.java:635)
at java.base/java.lang.Thread.run(Thread.java:833)
]]>
    </failure>
  </testcase> <!-- loginByGiving10NumbersAs0MobileNumberErrorTest -->
  <system-out/>
  <testcase classname="S2_Negative_Scenarious_for_SignupLoginSchemesDepositAmountSprint_1_Stg.Done_LoginErrors_StgTest" name="loginByGiving1stNumberAs0MobileNumberErrorTest" time="10.143">
    <failure message="null" type="java.lang.AssertionError">
      <![CDATA[java.lang.AssertionError: null
at org.testng.Assert.fail(Assert.java:110)
at org.testng.Assert.fail(Assert.java:115)
at S2_Negative_Scenarious_for_SignupLoginSchemesDepositAmountSprint_1_Stg.Done_LoginErrors_StgTest.loginByGiving1stNumberAs0MobileNumberErrorTest(Done_LoginErrors_StgTest.java:897)
at java.base/jdk.internal.reflect.DirectMethodHandleAccessor.invoke(DirectMethodHandleAccessor.java:104)
at java.base/java.lang.reflect.Method.invoke(Method.java:577)
at org.testng.internal.invokers.MethodInvocationHelper.invokeMethod(MethodInvocationHelper.java:139)
at org.testng.internal.invokers.TestInvoker.invokeMethod(TestInvoker.java:677)
at org.testng.internal.invokers.TestInvoker.invokeTestMethod(TestInvoker.java:221)
at org.testng.internal.invokers.MethodRunner.runInSequence(MethodRunner.java:50)
at org.testng.internal.invokers.TestInvoker$MethodInvocationAgent.invoke(TestInvoker.java:962)
at org.testng.internal.invokers.TestInvoker.invokeTestMethods(TestInvoker.java:194)
at org.testng.internal.invokers.TestMethodWorker.invokeTestMethods(TestMethodWorker.java:148)
at org.testng.internal.invokers.TestMethodWorker.run(TestMethodWorker.java:128)
at java.base/java.util.ArrayList.forEach(ArrayList.java:1511)
at org.testng.TestRunner.privateRun(TestRunner.java:806)
at org.testng.TestRunner.run(TestRunner.java:601)
at org.testng.SuiteRunner.runTest(SuiteRunner.java:433)
at org.testng.SuiteRunner$SuiteWorker.run(SuiteRunner.java:471)
at org.testng.internal.thread.ThreadUtil.lambda$execute$0(ThreadUtil.java:58)
at java.base/java.util.concurrent.FutureTask.run(FutureTask.java:264)
at java.base/java.util.concurrent.ThreadPoolExecutor.runWorker(ThreadPoolExecutor.java:1136)
at java.base/java.util.concurrent.ThreadPoolExecutor$Worker.run(ThreadPoolExecutor.java:635)
at java.base/java.lang.Thread.run(Thread.java:833)
]]>
    </failure>
  </testcase> <!-- loginByGiving1stNumberAs0MobileNumberErrorTest -->
  <system-out/>
</testsuite> <!-- S2_Negative_Scenarious_for_SignupLoginSchemesDepositAmountSprint_1_Stg.Done_LoginErrors_StgTest -->
